Traceback (most recent call last):
  File "/home/panciottig/gabrielepanciotti/Thesis-Streptococcus-Classification/env/lib/python3.10/site-packages/pandas/core/indexes/base.py", line 3653, in get_loc
    return self._engine.get_loc(casted_key)
  File "pandas/_libs/index.pyx", line 147, in pandas._libs.index.IndexEngine.get_loc
  File "pandas/_libs/index.pyx", line 176, in pandas._libs.index.IndexEngine.get_loc
  File "pandas/_libs/hashtable_class_helper.pxi", line 2606, in pandas._libs.hashtable.Int64HashTable.get_item
  File "pandas/_libs/hashtable_class_helper.pxi", line 2630, in pandas._libs.hashtable.Int64HashTable.get_item
KeyError: 3363

The above exception was the direct cause of the following exception:

Traceback (most recent call last):
  File "/home/panciottig/gabrielepanciotti/Thesis-Streptococcus-Classification/env/lib/python3.10/site-packages/pandas/core/frame.py", line 4110, in _set_item_mgr
    loc = self._info_axis.get_loc(key)
  File "/home/panciottig/gabrielepanciotti/Thesis-Streptococcus-Classification/env/lib/python3.10/site-packages/pandas/core/indexes/base.py", line 3655, in get_loc
    raise KeyError(key) from err
KeyError: 3363

During handling of the above exception, another exception occurred:

Traceback (most recent call last):
  File "/home/panciottig/gabrielepanciotti/Thesis-Streptococcus-Classification/scripts/3_Training_Models.py", line 418, in <module>
    maldi[i] = 0
  File "/home/panciottig/gabrielepanciotti/Thesis-Streptococcus-Classification/env/lib/python3.10/site-packages/pandas/core/frame.py", line 3950, in __setitem__
    self._set_item(key, value)
  File "/home/panciottig/gabrielepanciotti/Thesis-Streptococcus-Classification/env/lib/python3.10/site-packages/pandas/core/frame.py", line 4156, in _set_item
    self._set_item_mgr(key, value)
  File "/home/panciottig/gabrielepanciotti/Thesis-Streptococcus-Classification/env/lib/python3.10/site-packages/pandas/core/frame.py", line 4113, in _set_item_mgr
    self._mgr.insert(len(self._info_axis), key, value)
  File "/home/panciottig/gabrielepanciotti/Thesis-Streptococcus-Classification/env/lib/python3.10/site-packages/pandas/core/internals/managers.py", line 1398, in insert
    new_axis = self.items.insert(loc, item)
  File "/home/panciottig/gabrielepanciotti/Thesis-Streptococcus-Classification/env/lib/python3.10/site-packages/pandas/core/indexes/base.py", line 6640, in insert
    item = self._validate_fill_value(item)
  File "/home/panciottig/gabrielepanciotti/Thesis-Streptococcus-Classification/env/lib/python3.10/site-packages/pandas/core/indexes/base.py", line 5085, in _validate_fill_value
    return np_can_hold_element(dtype, value)
  File "/home/panciottig/gabrielepanciotti/Thesis-Streptococcus-Classification/env/lib/python3.10/site-packages/pandas/core/dtypes/cast.py", line 1782, in np_can_hold_element
    info = np.iinfo(dtype)
  File "/home/panciottig/gabrielepanciotti/Thesis-Streptococcus-Classification/env/lib/python3.10/site-packages/numpy/core/getlimits.py", line 693, in __init__
    if self.kind not in 'iu':
KeyboardInterrupt
